<?xml version="1.0" ?>
<!-- =================================================================================== -->
<!-- |    This document was autogenerated by xacro from /home/docker/ros2_ws/install/mm_description/share/mm_description/urdf/load_mobile_manipulator.xacro | -->
<!-- |    EDITING THIS FILE BY HAND IS NOT RECOMMENDED                                 | -->
<!-- =================================================================================== -->
<robot name="mobile_manipulator">
<!-- <xacro:arg name="robot_type" default=""/>
-->
<!-- <xacro:arg name="name" default="" />
-->
<!-- <xacro:arg name default="" />
-->
<!-- <xacro:arg name="geometry_parameters_file" default="$(find swerve_drive_description)/config/$(arg robot_type)/geometry_parameters.yaml" />
-->
<!-- <xacro:arg name="physical_parameters_file" default="$(find swerve_drive_description)/config/$(arg robot_type)/physical_parameters.yaml" />
-->
<!-- Base UR robot series xacro macro.
NOTE this is NOT a URDF. It cannot directly be loaded by consumers expecting a flattened '.urdf' package. See the top-level '.xacro' for that (but note that .xacro must still be processed by the xacro command).
This package models the base kinematic chain of a UR robot, which then gets parameterised by various configuration files to convert it into a UR3(e), UR5(e), UR10(e) or UR16e.
NOTE the default kinematic parameters (i.e., link lengths, frame locations, offsets, etc) do not correspond to any particular robot. They are defaults only. There WILL be non-zero offsets between the Forward Kinematics results in TF (i.e., robot_state_publisher) and the values reported by the Teach Pendant.
For accurate (and robot-specific) transforms, the 'kinematics_parameters_file' parameter MUST point to a .yaml package containing the appropriate values for the targeted robot.
If using the UniversalRobots/Universal_Robots_ROS_Driver, follow the steps described in the readme of that repository to extract the kinematic calibration from the controller and generate the required .yaml package.
Main author of the migration to yaml configs Ludovic Delval.
Contributors to previous versions (in no particular order)
- Denis Stogl - Lovro Ivanov - Felix Messmer - Kelsey Hawkins - Wim Meeussen - Shaun Edwards - Nadia Hammoudeh Garcia - Dave Hershberger - G. vd. Hoorn - Philip Long - Dave Coleman - Miguel Prada - Mathias Luedtke - Marcel Schnirring - Felix von Drigalski - Felix Exner - Jimmy Da Silva - Ajit Krisshna N L - Muhammad Asif Rana -->
<!-- NOTE the macro defined in this package is NOT part of the public API of this package. Users CANNOT rely on this package being available, or stored in this location. Nor can they rely on the existence of the macro. -->
<!-- <xacro:macro name="cylinder_inertial" params="radius length mass *origin">
<inertial>
<mass value="2" />
<xacro:insert_block name="origin" />
<inertia ixx="0.01" ixy="0.0" ixz="0.0" iyy="0.01" iyz="0.0" izz="0.01" />
</inertial>
</xacro:macro>
-->
<!-- parses the transmission tags and loads the appropriate hardware interfaces and controller manager -->
<!-- convert to property to use substitution in function -->
<!-- <xacro:property name="initial_positions_file" default="$(arg initial_positions_file)"/>
-->

<link name="world"/>
<link name="virtual1"/>
<link name="virtual2"/>

<joint name="virtual_joint0" type="prismatic">
    <origin rpy="0 0 0" xyz="0 0 0"/>
    <parent link="world"/>
    <child link="virtual1"/>
    <axis xyz="1 0 0"/>
    <limit effort="87" velocity="0.6"/>
</joint>
    <joint name="virtual_joint1" type="prismatic">
    <origin rpy="0 0 0" xyz="0 0 0"/>
    <parent link="virtual1"/>
    <child link="virtual2"/>
    <axis xyz="0 1 0"/>
    <limit effort="87" velocity="0.6"/>
</joint>
    <joint name="virtual_joint2" type="continuous">
    <origin rpy="0 0 0" xyz="0 0 0"/>
    <parent link="virtual2"/>
    <child link="mobile_base_footprint"/>
    <axis xyz="0 0 1"/>
    <limit effort="87"  velocity="1.2"/>
</joint>

<link name="mobile_base_footprint"/>
<joint name="mobile_base_joint " type="fixed">
<origin rpy="0 0 0" xyz="0 0 0.44"/>
<parent link="mobile_base_footprint"/>
<child link="mobile_base_link"/>
</joint>
<link name="mobile_base_link">
<inertial>
<origin rpy="0 0 0" xyz="0 0 -0.2"/>
<mass value="40"/>
<inertia ixx="1.2" ixy="0" ixz="0" iyy="1.5" iyz="0" izz="2"/>
</inertial>
<visual>
<origin rpy="0 0 0" xyz="0 0 0"/>
<geometry>
<mesh filename="file://$(find mm_description)/meshes/yhs_fw01/base_link_collision.STL"/>
</geometry>
<material name="">
<color rgba="0.75294 0.75294 0.75294 1"/>
</material>
</visual>
<collision>
<origin rpy="0 0 0" xyz="0 0 0"/>
<geometry>
<mesh filename="file://$(find mm_description)/meshes/yhs_fw01/base_link_collision.STL"/>
</geometry>
</collision>
</link>
<link name="mobile_lf_swerve_link">
<inertial>
<origin rpy="0 0 0" xyz="0 0.05 -0.12"/>
<mass value="2"/>
<inertia ixx="0.01" ixy="0" ixz="0" iyy="0.01" iyz="0" izz="0.01"/>
</inertial>
<visual>
<origin rpy="0 0 0" xyz="0 0 0"/>
<geometry>
<mesh filename="file://$(find mm_description)/meshes/yhs_fw01/swerve_link_collision.STL"/>
</geometry>
<material name="">
<color rgba="0.75294 0.75294 0.75294 1"/>
</material>
</visual>
<collision>
<origin rpy="0 0 0" xyz="0 0 0"/>
<geometry>
<mesh filename="file://$(find mm_description)/meshes/yhs_fw01/swerve_link_collision.STL"/>
</geometry>
</collision>
</link>
<joint name="mobile_lf_swerve_joint" type="fixed">
<origin rpy="0 0 3.141592653589793" xyz="0.2 0.21 -0.113"/>
<parent link="mobile_base_link"/>
<child link="mobile_lf_swerve_link"/>
<axis xyz="0 0 1"/>
<limit effort="100" velocity="3.2"/>
<!-- <dynamics damping="100" friction="10" />
-->
</joint>
<link name="mobile_lf_wheel_link">
<inertial>
<origin rpy="0 0 0" xyz="0 -0.0075 0"/>
<mass value="2"/>
<inertia ixx="0.01" ixy="0" ixz="0" iyy="0.01" iyz="0" izz="0.01"/>
</inertial>
<visual>
<origin rpy="0 0 0" xyz="0 0 0"/>
<geometry>
<mesh filename="file://$(find mm_description)/meshes/yhs_fw01/wheel_link_collision.STL"/>
</geometry>
<material name="">
<color rgba="0.75294 0.75294 0.75294 1"/>
</material>
</visual>
<collision>
<origin rpy="0 0 0" xyz="0 0 0"/>
<geometry>
<mesh filename="file://$(find mm_description)/meshes/yhs_fw01/wheel_link_collision.STL"/>
</geometry>
</collision>
</link>
<joint name="mobile_lf_wheel_joint" type="fixed">
<origin rpy="0 0 0" xyz="0 0 -0.207"/>
<parent link="mobile_lf_swerve_link"/>
<child link="mobile_lf_wheel_link"/>
<axis xyz="0 -1 0"/>
<limit effort="30" velocity="12.7"/>
<!-- <dynamics damping="0.4" friction="0.04" />
-->
</joint>
<link name="mobile_lf_wheel_arrow_link">
<visual>
<origin rpy="0 0 0" xyz="0 0 0.05"/>
<geometry>
<box size="0.02 0.02 0.1"/>
</geometry>
<material name="">
<color rgba="0.75294 0.75294 0.75294 1"/>
</material>
</visual>
</link>
<joint name="mobile_lf_wheel_arrow_joint" type="fixed">
<origin rpy="0 0 0" xyz="0 -0.04 0"/>
<parent link="mobile_lf_wheel_link"/>
<child link="mobile_lf_wheel_arrow_link"/>
</joint>
<gazebo reference="mobile_lf_swerve_link">
<!-- <mu1 value="0.1"/>
-->
<!-- <mu2 value="0.1"/>
-->
<material>Gazebo/Black</material>
<selfCollide>false</selfCollide>
</gazebo>
<gazebo reference="mobile_lf_wheel_link">
<!-- <mu value="100000.0"/>
-->
<!-- <mu1 value="100000.0"/>
-->
<!-- <mu2 value="100000.0"/>
-->
<!-- <soft_cfm value="0" />
-->
<!-- <soft_erp value="0.02" />
-->
<kp value="100000.0"/>
<kd value="10000000000000.0"/>
<!-- <max_vel value="0.01" />
-->
<!-- <min_vel value="0.001" />
-->
<!-- <fdir1 value="0 0 0"/>
-->
<material>Gazebo/Blue</material>
<selfCollide>false</selfCollide>
</gazebo>
<gazebo reference="mobile_lf_swerve_joint">
<implicitSpringDamper>True</implicitSpringDamper>
</gazebo>
<gazebo reference="mobile_lf_wheel_joint">
<implicitSpringDamper>True</implicitSpringDamper>
</gazebo>
<link name="mobile_rf_swerve_link">
<inertial>
<origin rpy="0 0 0" xyz="0 0.05 -0.12"/>
<mass value="2"/>
<inertia ixx="0.01" ixy="0" ixz="0" iyy="0.01" iyz="0" izz="0.01"/>
</inertial>
<visual>
<origin rpy="0 0 0" xyz="0 0 0"/>
<geometry>
<mesh filename="file://$(find mm_description)/meshes/yhs_fw01/swerve_link_collision.STL"/>
</geometry>
<material name="">
<color rgba="0.75294 0.75294 0.75294 1"/>
</material>
</visual>
<collision>
<origin rpy="0 0 0" xyz="0 0 0"/>
<geometry>
<mesh filename="file://$(find mm_description)/meshes/yhs_fw01/swerve_link_collision.STL"/>
</geometry>
</collision>
</link>
<joint name="mobile_rf_swerve_joint" type="fixed">
<origin rpy="0 0 0" xyz="0.2 -0.21 -0.113"/>
<parent link="mobile_base_link"/>
<child link="mobile_rf_swerve_link"/>
<axis xyz="0 0 1"/>
<limit effort="100" velocity="3.2"/>
<!-- <dynamics damping="100" friction="10" />
-->
</joint>
<link name="mobile_rf_wheel_link">
<inertial>
<origin rpy="0 0 0" xyz="0 -0.0075 0"/>
<mass value="2"/>
<inertia ixx="0.01" ixy="0" ixz="0" iyy="0.01" iyz="0" izz="0.01"/>
</inertial>
<visual>
<origin rpy="0 0 0" xyz="0 0 0"/>
<geometry>
<mesh filename="file://$(find mm_description)/meshes/yhs_fw01/wheel_link_collision.STL"/>
</geometry>
<material name="">
<color rgba="0.75294 0.75294 0.75294 1"/>
</material>
</visual>
<collision>
<origin rpy="0 0 0" xyz="0 0 0"/>
<geometry>
<mesh filename="file://$(find mm_description)/meshes/yhs_fw01/wheel_link_collision.STL"/>
</geometry>
</collision>
</link>
<joint name="mobile_rf_wheel_joint" type="fixed">
<origin rpy="0 0 0" xyz="0 0 -0.207"/>
<parent link="mobile_rf_swerve_link"/>
<child link="mobile_rf_wheel_link"/>
<axis xyz="0 1 0"/>
<limit effort="30" velocity="12.7"/>
<!-- <dynamics damping="0.4" friction="0.04" />
-->
</joint>
<link name="mobile_rf_wheel_arrow_link">
<visual>
<origin rpy="0 0 0" xyz="0 0 0.05"/>
<geometry>
<box size="0.02 0.02 0.1"/>
</geometry>
<material name="">
<color rgba="0.75294 0.75294 0.75294 1"/>
</material>
</visual>
</link>
<joint name="mobile_rf_wheel_arrow_joint" type="fixed">
<origin rpy="0 0 0" xyz="0 -0.04 0"/>
<parent link="mobile_rf_wheel_link"/>
<child link="mobile_rf_wheel_arrow_link"/>
</joint>
<gazebo reference="mobile_rf_swerve_link">
<!-- <mu1 value="0.1"/>
-->
<!-- <mu2 value="0.1"/>
-->
<material>Gazebo/Black</material>
<selfCollide>false</selfCollide>
</gazebo>
<gazebo reference="mobile_rf_wheel_link">
<!-- <mu value="100000.0"/>
-->
<!-- <mu1 value="100000.0"/>
-->
<!-- <mu2 value="100000.0"/>
-->
<!-- <soft_cfm value="0" />
-->
<!-- <soft_erp value="0.02" />
-->
<kp value="100000.0"/>
<kd value="10000000000000.0"/>
<!-- <max_vel value="0.01" />
-->
<!-- <min_vel value="0.001" />
-->
<!-- <fdir1 value="0 0 0"/>
-->
<material>Gazebo/Blue</material>
<selfCollide>false</selfCollide>
</gazebo>
<gazebo reference="mobile_rf_swerve_joint">
<implicitSpringDamper>True</implicitSpringDamper>
</gazebo>
<gazebo reference="mobile_rf_wheel_joint">
<implicitSpringDamper>True</implicitSpringDamper>
</gazebo>
<link name="mobile_rr_swerve_link">
<inertial>
<origin rpy="0 0 0" xyz="0 0.05 -0.12"/>
<mass value="2"/>
<inertia ixx="0.01" ixy="0" ixz="0" iyy="0.01" iyz="0" izz="0.01"/>
</inertial>
<visual>
<origin rpy="0 0 0" xyz="0 0 0"/>
<geometry>
<mesh filename="file://$(find mm_description)/meshes/yhs_fw01/swerve_link_collision.STL"/>
</geometry>
<material name="">
<color rgba="0.75294 0.75294 0.75294 1"/>
</material>
</visual>
<collision>
<origin rpy="0 0 0" xyz="0 0 0"/>
<geometry>
<mesh filename="file://$(find mm_description)/meshes/yhs_fw01/swerve_link_collision.STL"/>
</geometry>
</collision>
</link>
<joint name="mobile_rr_swerve_joint" type="fixed">
<origin rpy="0 0 0" xyz="-0.2 -0.21 -0.113"/>
<parent link="mobile_base_link"/>
<child link="mobile_rr_swerve_link"/>
<axis xyz="0 0 1"/>
<limit effort="100" velocity="3.2"/>
<!-- <dynamics damping="100" friction="10" />
-->
</joint>
<link name="mobile_rr_wheel_link">
<inertial>
<origin rpy="0 0 0" xyz="0 -0.0075 0"/>
<mass value="2"/>
<inertia ixx="0.01" ixy="0" ixz="0" iyy="0.01" iyz="0" izz="0.01"/>
</inertial>
<visual>
<origin rpy="0 0 0" xyz="0 0 0"/>
<geometry>
<mesh filename="file://$(find mm_description)/meshes/yhs_fw01/wheel_link_collision.STL"/>
</geometry>
<material name="">
<color rgba="0.75294 0.75294 0.75294 1"/>
</material>
</visual>
<collision>
<origin rpy="0 0 0" xyz="0 0 0"/>
<geometry>
<mesh filename="file://$(find mm_description)/meshes/yhs_fw01/wheel_link_collision.STL"/>
</geometry>
</collision>
</link>
<joint name="mobile_rr_wheel_joint" type="fixed">
<origin rpy="0 0 0" xyz="0 0 -0.207"/>
<parent link="mobile_rr_swerve_link"/>
<child link="mobile_rr_wheel_link"/>
<axis xyz="0 1 0"/>
<limit effort="30" velocity="12.7"/>
<!-- <dynamics damping="0.4" friction="0.04" />
-->
</joint>
<link name="mobile_rr_wheel_arrow_link">
<visual>
<origin rpy="0 0 0" xyz="0 0 0.05"/>
<geometry>
<box size="0.02 0.02 0.1"/>
</geometry>
<material name="">
<color rgba="0.75294 0.75294 0.75294 1"/>
</material>
</visual>
</link>
<joint name="mobile_rr_wheel_arrow_joint" type="fixed">
<origin rpy="0 0 0" xyz="0 -0.04 0"/>
<parent link="mobile_rr_wheel_link"/>
<child link="mobile_rr_wheel_arrow_link"/>
</joint>
<gazebo reference="mobile_rr_swerve_link">
<!-- <mu1 value="0.1"/>
-->
<!-- <mu2 value="0.1"/>
-->
<material>Gazebo/Black</material>
<selfCollide>false</selfCollide>
</gazebo>
<gazebo reference="mobile_rr_wheel_link">
<!-- <mu value="100000.0"/>
-->
<!-- <mu1 value="100000.0"/>
-->
<!-- <mu2 value="100000.0"/>
-->
<!-- <soft_cfm value="0" />
-->
<!-- <soft_erp value="0.02" />
-->
<kp value="100000.0"/>
<kd value="10000000000000.0"/>
<!-- <max_vel value="0.01" />
-->
<!-- <min_vel value="0.001" />
-->
<!-- <fdir1 value="0 0 0"/>
-->
<material>Gazebo/Blue</material>
<selfCollide>false</selfCollide>
</gazebo>
<gazebo reference="mobile_rr_swerve_joint">
<implicitSpringDamper>True</implicitSpringDamper>
</gazebo>
<gazebo reference="mobile_rr_wheel_joint">
<implicitSpringDamper>True</implicitSpringDamper>
</gazebo>
<link name="mobile_lr_swerve_link">
<inertial>
<origin rpy="0 0 0" xyz="0 0.05 -0.12"/>
<mass value="2"/>
<inertia ixx="0.01" ixy="0" ixz="0" iyy="0.01" iyz="0" izz="0.01"/>
</inertial>
<visual>
<origin rpy="0 0 0" xyz="0 0 0"/>
<geometry>
<mesh filename="file://$(find mm_description)/meshes/yhs_fw01/swerve_link_collision.STL"/>
</geometry>
<material name="">
<color rgba="0.75294 0.75294 0.75294 1"/>
</material>
</visual>
<collision>
<origin rpy="0 0 0" xyz="0 0 0"/>
<geometry>
<mesh filename="file://$(find mm_description)/meshes/yhs_fw01/swerve_link_collision.STL"/>
</geometry>
</collision>
</link>
<joint name="mobile_lr_swerve_joint" type="fixed">
<origin rpy="0 0 3.141592653589793" xyz="-0.2 0.21 -0.113"/>
<parent link="mobile_base_link"/>
<child link="mobile_lr_swerve_link"/>
<axis xyz="0 0 1"/>
<limit effort="100" velocity="3.2"/>
<!-- <dynamics damping="100" friction="10" />
-->
</joint>
<link name="mobile_lr_wheel_link">
<inertial>
<origin rpy="0 0 0" xyz="0 -0.0075 0"/>
<mass value="2"/>
<inertia ixx="0.01" ixy="0" ixz="0" iyy="0.01" iyz="0" izz="0.01"/>
</inertial>
<visual>
<origin rpy="0 0 0" xyz="0 0 0"/>
<geometry>
<mesh filename="file://$(find mm_description)/meshes/yhs_fw01/wheel_link_collision.STL"/>
</geometry>
<material name="">
<color rgba="0.75294 0.75294 0.75294 1"/>
</material>
</visual>
<collision>
<origin rpy="0 0 0" xyz="0 0 0"/>
<geometry>
<mesh filename="file://$(find mm_description)/meshes/yhs_fw01/wheel_link_collision.STL"/>
</geometry>
</collision>
</link>
<joint name="mobile_lr_wheel_joint" type="fixed">
<origin rpy="0 0 0" xyz="0 0 -0.207"/>
<parent link="mobile_lr_swerve_link"/>
<child link="mobile_lr_wheel_link"/>
<axis xyz="0 -1 0"/>
<limit effort="30" velocity="12.7"/>
<!-- <dynamics damping="0.4" friction="0.04" />
-->
</joint>
<link name="mobile_lr_wheel_arrow_link">
<visual>
<origin rpy="0 0 0" xyz="0 0 0.05"/>
<geometry>
<box size="0.02 0.02 0.1"/>
</geometry>
<material name="">
<color rgba="0.75294 0.75294 0.75294 1"/>
</material>
</visual>
</link>
<joint name="mobile_lr_wheel_arrow_joint" type="fixed">
<origin rpy="0 0 0" xyz="0 -0.04 0"/>
<parent link="mobile_lr_wheel_link"/>
<child link="mobile_lr_wheel_arrow_link"/>
</joint>
<gazebo reference="mobile_lr_swerve_link">
<!-- <mu1 value="0.1"/>
-->
<!-- <mu2 value="0.1"/>
-->
<material>Gazebo/Black</material>
<selfCollide>false</selfCollide>
</gazebo>
<gazebo reference="mobile_lr_wheel_link">
<!-- <mu value="100000.0"/>
-->
<!-- <mu1 value="100000.0"/>
-->
<!-- <mu2 value="100000.0"/>
-->
<!-- <soft_cfm value="0" />
-->
<!-- <soft_erp value="0.02" />
-->
<kp value="100000.0"/>
<kd value="10000000000000.0"/>
<!-- <max_vel value="0.01" />
-->
<!-- <min_vel value="0.001" />
-->
<!-- <fdir1 value="0 0 0"/>
-->
<material>Gazebo/Blue</material>
<selfCollide>false</selfCollide>
</gazebo>
<gazebo reference="mobile_lr_swerve_joint">
<implicitSpringDamper>True</implicitSpringDamper>
</gazebo>
<gazebo reference="mobile_lr_wheel_joint">
<implicitSpringDamper>True</implicitSpringDamper>
</gazebo>
<gazebo reference="mobile_base_link">
<mu1>0.2</mu1>
<mu2>0.2</mu2>
<material>Gazebo/White</material>
<selfCollide>false</selfCollide>
</gazebo>
<link name="mobile_imu_link"/>
<joint name="mobile_imu_joint" type="fixed">
<parent link="mobile_base_link"/>
<child link="mobile_imu_link"/>
<origin rpy="0 0 0" xyz="0 0 0"/>
</joint>
<link name="mobile_lidar_link">
<visual>
<origin rpy="0 0 0" xyz="0 0 0"/>
<geometry>
<cylinder length="0.06" radius="0.06"/>
</geometry>
<material name="">
<color rgba="0.75294 0.75294 0.75294 1"/>
</material>
</visual>
<collision>
<origin rpy="0 0 0" xyz="0 0 0"/>
<geometry>
<cylinder length="0.06" radius="0.06"/>
</geometry>
</collision>
<inertial>
<mass value="0.1"/>
<origin xyz="0 0 0"/>
<inertia ixx="0.001" ixy="0.0" ixz="0.0" iyy="0.001" iyz="0.0" izz="0.001"/>
</inertial>
</link>
<joint name="mobile_lidar_joint" type="fixed">
<parent link="mobile_base_link"/>
<child link="mobile_lidar_link"/>
<origin rpy="0 0 0" xyz="0 0 0.03"/>
</joint>
<gazebo reference="mobile_lidar_link">
<sensor name="lidar2d" type="ray">
<always_on>true</always_on>
<!-- <visualize>false</visualize>
-->
<pose>0 0 0 0 0 0</pose>
<update_rate>30</update_rate>
<ray>
<scan>
<horizontal>
<samples>360</samples>
<resolution>1.000000</resolution>
<min_angle>0.000000</min_angle>
<max_angle>6.280000</max_angle>
</horizontal>
</scan>
<range>
<min>0.120000</min>
<max>5</max>
<resolution>0.015000</resolution>
</range>
<noise>
<type>gaussian</type>
<mean>0.0</mean>
<stddev>0.01</stddev>
</noise>
</ray>
<plugin filename="libgazebo_ros_ray_sensor.so" name="lidar2d">
<ros>
<remapping>~/out:=scan</remapping>
</ros>
<output_type>sensor_msgs/LaserScan</output_type>
<frame_name>mobile_lidar_link</frame_name>
</plugin>
</sensor>
</gazebo>
<gazebo reference="mobile_imu_link">
<sensor name="imu" type="imu">
<always_on>true</always_on>
<update_rate>200</update_rate>
<imu>
<angular_velocity>
<x>
<noise type="gaussian">
<mean>0.0</mean>
<stddev>2e-4</stddev>
</noise>
</x>
<y>
<noise type="gaussian">
<mean>0.0</mean>
<stddev>2e-4</stddev>
</noise>
</y>
<z>
<noise type="gaussian">
<mean>0.0</mean>
<stddev>2e-4</stddev>
</noise>
</z>
</angular_velocity>
<linear_acceleration>
<x>
<noise type="gaussian">
<mean>0.0</mean>
<stddev>1.7e-2</stddev>
</noise>
</x>
<y>
<noise type="gaussian">
<mean>0.0</mean>
<stddev>1.7e-2</stddev>
</noise>
</y>
<z>
<noise type="gaussian">
<mean>0.0</mean>
<stddev>1.7e-2</stddev>
</noise>
</z>
</linear_acceleration>
</imu>
<plugin filename="libgazebo_ros_imu_sensor.so" name="imu">
<ros>
<remapping>~/out:=imu</remapping>
</ros>
</plugin>
</sensor>
</gazebo>
<ros2_control name="mobile_manipulator" type="system">
<hardware>
<plugin>gazebo_ros2_control/GazeboSystem</plugin>
</hardware>
<joint name="shoulder_pan_joint">
<command_interface name="position">
<param name="min">{-2*pi}</param>
<param name="max">{2*pi}</param>
</command_interface>
<command_interface name="velocity">
<param name="min">-3.15</param>
<param name="max">3.15</param>
</command_interface>
<state_interface name="position">
<!-- initial position for the FakeSystem and simulation -->
<param name="initial_value">0.0</param>
</state_interface>
<state_interface name="velocity"/>
<state_interface name="effort"/>
</joint>
<joint name="shoulder_lift_joint">
<command_interface name="position">
<param name="min">{-2*pi}</param>
<param name="max">{2*pi}</param>
</command_interface>
<command_interface name="velocity">
<param name="min">-3.15</param>
<param name="max">3.15</param>
</command_interface>
<state_interface name="position">
<!-- initial position for the FakeSystem and simulation -->
<param name="initial_value">-1.57</param>
</state_interface>
<state_interface name="velocity"/>
<state_interface name="effort"/>
</joint>
<joint name="elbow_joint">
<command_interface name="position">
<param name="min">{-pi}</param>
<param name="max">{pi}</param>
</command_interface>
<command_interface name="velocity">
<param name="min">-3.15</param>
<param name="max">3.15</param>
</command_interface>
<state_interface name="position">
<!-- initial position for the FakeSystem and simulation -->
<param name="initial_value">0.0</param>
</state_interface>
<state_interface name="velocity"/>
<state_interface name="effort"/>
</joint>
<joint name="wrist_1_joint">
<command_interface name="position">
<param name="min">{-2*pi}</param>
<param name="max">{2*pi}</param>
</command_interface>
<command_interface name="velocity">
<param name="min">-3.2</param>
<param name="max">3.2</param>
</command_interface>
<state_interface name="position">
<!-- initial position for the FakeSystem and simulation -->
<param name="initial_value">-1.57</param>
</state_interface>
<state_interface name="velocity"/>
<state_interface name="effort"/>
</joint>
<joint name="wrist_2_joint">
<command_interface name="position">
<param name="min">{-2*pi}</param>
<param name="max">{2*pi}</param>
</command_interface>
<command_interface name="velocity">
<param name="min">-3.2</param>
<param name="max">3.2</param>
</command_interface>
<state_interface name="position">
<!-- initial position for the FakeSystem and simulation -->
<param name="initial_value">0.0</param>
</state_interface>
<state_interface name="velocity"/>
<state_interface name="effort"/>
</joint>
<joint name="wrist_3_joint">
<command_interface name="position">
<param name="min">{-2*pi}</param>
<param name="max">{2*pi}</param>
</command_interface>
<command_interface name="velocity">
<param name="min">-3.2</param>
<param name="max">3.2</param>
</command_interface>
<state_interface name="position">
<!-- initial position for the FakeSystem and simulation -->
<param name="initial_value">0.0</param>
</state_interface>
<state_interface name="velocity"/>
<state_interface name="effort"/>
</joint>
</ros2_control>
<!-- Add URDF transmission elements (for ros_control) -->
<!--<xacro:ur_arm_transmissio"" hw_interface="${transmission_hw_interface}" />-->
<!-- Placeholder for ros2_control transmission which don't yet exist -->
<!-- links -  main serial chain -->
<link name="base_link"/>
<link name="base_link_inertia">
<visual>
<origin rpy="0 0 3.141592653589793" xyz="0 0 0"/>
<geometry>
<mesh filename="file://$(find ur_description)/meshes/ur10e/visual/base.dae"/>
</geometry>
</visual>
<collision>
<origin rpy="0 0 3.141592653589793" xyz="0 0 0"/>
<geometry>
<mesh filename="file://$(find ur_description)/meshes/ur10e/collision/base.stl"/>
</geometry>
</collision>
<inertial>
<mass value="4.0"/>
<origin rpy="0 0 0" xyz="0 0 0"/>
<inertia ixx="0.0061063308908" ixy="0.0" ixz="0.0" iyy="0.0061063308908" iyz="0.0" izz="0.01125"/>
</inertial>
</link>
<link name="shoulder_link">
<visual>
<origin rpy="0 0 3.141592653589793" xyz="0 0 0"/>
<geometry>
<mesh filename="file://$(find ur_description)/meshes/ur10e/visual/shoulder.dae"/>
</geometry>
</visual>
<collision>
<origin rpy="0 0 3.141592653589793" xyz="0 0 0"/>
<geometry>
<mesh filename="file://$(find ur_description)/meshes/ur10e/collision/shoulder.stl"/>
</geometry>
</collision>
<inertial>
<mass value="7.778"/>
<origin rpy="0 0 0" xyz="0 0 0"/>
<inertia ixx="0.03147431257693659" ixy="0.0" ixz="0.0" iyy="0.03147431257693659" iyz="0.0" izz="0.021875624999999996"/>
</inertial>
</link>
<link name="upper_arm_link">
<visual>
<origin rpy="1.5707963267948966 0 -1.5707963267948966" xyz="0 0 0.1762"/>
<geometry>
<mesh filename="file://$(find ur_description)/meshes/ur10e/visual/upperarm.dae"/>
</geometry>
</visual>
<collision>
<origin rpy="1.5707963267948966 0 -1.5707963267948966" xyz="0 0 0.1762"/>
<geometry>
<mesh filename="file://$(find ur_description)/meshes/ur10e/collision/upperarm.stl"/>
</geometry>
</collision>
<inertial>
<mass value="12.93"/>
<origin rpy="0 0 0" xyz="0 0 0"/>
<inertia ixx="0.42175380379841093" ixy="0.0" ixz="0.0" iyy="0.42175380379841093" iyz="0.0" izz="0.03636562499999999"/>
</inertial>
</link>
<link name="forearm_link">
<visual>
<origin rpy="1.5707963267948966 0 -1.5707963267948966" xyz="0 0 0.0393"/>
<geometry>
<mesh filename="file://$(find ur_description)/meshes/ur10e/visual/forearm.dae"/>
</geometry>
</visual>
<collision>
<origin rpy="1.5707963267948966 0 -1.5707963267948966" xyz="0 0 0.0393"/>
<geometry>
<mesh filename="file://$(find ur_description)/meshes/ur10e/collision/forearm.stl"/>
</geometry>
</collision>
<inertial>
<mass value="3.87"/>
<origin rpy="0 0 0" xyz="0 0 0"/>
<inertia ixx="0.11079302548902206" ixy="0.0" ixz="0.0" iyy="0.11079302548902206" iyz="0.0" izz="0.010884375"/>
</inertial>
</link>
<link name="wrist_1_link">
<visual>
<origin rpy="1.5707963267948966 0 0" xyz="0 0 -0.135"/>
<geometry>
<mesh filename="file://$(find ur_description)/meshes/ur10e/visual/wrist1.dae"/>
</geometry>
</visual>
<collision>
<origin rpy="1.5707963267948966 0 0" xyz="0 0 -0.135"/>
<geometry>
<mesh filename="file://$(find ur_description)/meshes/ur10e/collision/wrist1.stl"/>
</geometry>
</collision>
<inertial>
<mass value="1.96"/>
<origin rpy="0 0 0" xyz="0 0 0"/>
<inertia ixx="0.005108247956699999" ixy="0.0" ixz="0.0" iyy="0.005108247956699999" iyz="0.0" izz="0.005512499999999999"/>
</inertial>
</link>
<link name="wrist_2_link">
<visual>
<origin rpy="0 0 0" xyz="0 0 -0.12"/>
<geometry>
<mesh filename="file://$(find ur_description)/meshes/ur10e/visual/wrist2.dae"/>
</geometry>
</visual>
<collision>
<origin rpy="0 0 0" xyz="0 0 -0.12"/>
<geometry>
<mesh filename="file://$(find ur_description)/meshes/ur10e/collision/wrist2.stl"/>
</geometry>
</collision>
<inertial>
<mass value="1.96"/>
<origin rpy="0 0 0" xyz="0 0 0"/>
<inertia ixx="0.005108247956699999" ixy="0.0" ixz="0.0" iyy="0.005108247956699999" iyz="0.0" izz="0.005512499999999999"/>
</inertial>
</link>
<link name="wrist_3_link">
<visual>
<origin rpy="1.5707963267948966 0 0" xyz="0 0 -0.1168"/>
<geometry>
<mesh filename="file://$(find ur_description)/meshes/ur10e/visual/wrist3.dae"/>
</geometry>
</visual>
<collision>
<origin rpy="1.5707963267948966 0 0" xyz="0 0 -0.1168"/>
<geometry>
<mesh filename="file://$(find ur_description)/meshes/ur10e/collision/wrist3.stl"/>
</geometry>
</collision>
<inertial>
<mass value="0.202"/>
<origin rpy="0 0 0" xyz="0 0 0"/>
<inertia ixx="0.00014434577559500002" ixy="0.0" ixz="0.0" iyy="0.00014434577559500002" iyz="0.0" izz="0.00020452500000000002"/>
</inertial>
</link>
<!-- base_joint fixes base_link to the environment -->
<joint name="base_joint" type="fixed">
<origin rpy="0 0 0" xyz="0 0 0.06"/>
<parent link="mobile_base_link"/>
<child link="base_link"/>
</joint>
<!-- joints - main serial chain -->
<joint name="base_link-base_link_inertia" type="fixed">
<parent link="base_link"/>
<child link="base_link_inertia"/>
<!-- 'base_link' is REP-103 aligned (so X+ forward), while the internal frames of the robot/controller have X+ pointing backwards. Use the joint between 'base_link' and 'base_link_inertia' (a dummy link/frame) to introduce the necessary rotation over Z (of pi rad). -->
<origin rpy="0 0 3.141592653589793" xyz="0 0 0"/>
</joint>
<joint name="shoulder_pan_joint" type="revolute">
<parent link="base_link_inertia"/>
<child link="shoulder_link"/>
<origin rpy="0 0 0" xyz="0 0 0.1807"/>
<axis xyz="0 0 1"/>
<limit effort="330.0" lower="-6.283185307179586" upper="6.283185307179586" velocity="2.0943951023931953"/>
<safety_controller k_position="20" k_velocity="0.0" soft_lower_limit="-6.133185307179586" soft_upper_limit="6.133185307179586"/>
<dynamics damping="50" friction="5"/>
<!-- <dynamics damping="0" friction="0"/>
-->
</joint>
<joint name="shoulder_lift_joint" type="revolute">
<parent link="shoulder_link"/>
<child link="upper_arm_link"/>
<origin rpy="1.570796327 0 0" xyz="0 0 0"/>
<axis xyz="0 0 1"/>
<limit effort="330.0" lower="-6.283185307179586" upper="6.283185307179586" velocity="2.0943951023931953"/>
<safety_controller k_position="20" k_velocity="0.0" soft_lower_limit="-6.133185307179586" soft_upper_limit="6.133185307179586"/>
<dynamics damping="50" friction="5"/>
<!-- <dynamics damping="0" friction="0"/>
-->
</joint>
<joint name="elbow_joint" type="revolute">
<parent link="upper_arm_link"/>
<child link="forearm_link"/>
<origin rpy="0 0 0" xyz="-0.6127 0 0"/>
<axis xyz="0 0 1"/>
<limit effort="150.0" lower="-3.141592653589793" upper="3.141592653589793" velocity="3.141592653589793"/>
<safety_controller k_position="20" k_velocity="0.0" soft_lower_limit="-2.991592653589793" soft_upper_limit="2.991592653589793"/>
<dynamics damping="50" friction="5"/>
<!-- <dynamics damping="0" friction="0"/>
-->
</joint>
<joint name="wrist_1_joint" type="revolute">
<parent link="forearm_link"/>
<child link="wrist_1_link"/>
<origin rpy="0 0 0" xyz="-0.57155 0 0.17415"/>
<axis xyz="0 0 1"/>
<limit effort="56.0" lower="-6.283185307179586" upper="6.283185307179586" velocity="3.141592653589793"/>
<safety_controller k_position="20" k_velocity="0.0" soft_lower_limit="-6.133185307179586" soft_upper_limit="6.133185307179586"/>
<dynamics damping="10" friction="1"/>
<!-- <dynamics damping="0" friction="0"/>
-->
</joint>
<joint name="wrist_2_joint" type="revolute">
<parent link="wrist_1_link"/>
<child link="wrist_2_link"/>
<origin rpy="1.570796327 0 0" xyz="0 -0.11985 -2.458164590756244e-11"/>
<axis xyz="0 0 1"/>
<limit effort="56.0" lower="-6.283185307179586" upper="6.283185307179586" velocity="3.141592653589793"/>
<safety_controller k_position="20" k_velocity="0.0" soft_lower_limit="-6.133185307179586" soft_upper_limit="6.133185307179586"/>
<dynamics damping="10" friction="1"/>
<!-- <dynamics damping="0" friction="0"/>
-->
</joint>
<joint name="wrist_3_joint" type="revolute">
<parent link="wrist_2_link"/>
<child link="wrist_3_link"/>
<origin rpy="1.570796326589793 3.141592653589793 3.141592653589793" xyz="0 0.11655 -2.390480459346185e-11"/>
<axis xyz="0 0 1"/>
<limit effort="56.0" lower="-6.283185307179586" upper="6.283185307179586" velocity="3.141592653589793"/>
<safety_controller k_position="20" k_velocity="0.0" soft_lower_limit="-6.133185307179586" soft_upper_limit="6.133185307179586"/>
<dynamics damping="10" friction="1"/>
<!-- <dynamics damping="0" friction="0"/>
-->
</joint>
<link name="ft_frame"/>
<joint name="wrist_3_link-ft_frame" type="fixed">
<parent link="wrist_3_link"/>
<child link="ft_frame"/>
<origin rpy="3.141592653589793 0 0" xyz="0 0 0"/>
</joint>
<!-- ROS-Industrial 'base' frame - base_link to UR 'Base' Coordinates transform -->
<link name="base"/>
<joint name="base_link-base_fixed_joint" type="fixed">
<!-- Note the rotation over Z of pi radians - as base_link is REP-103 aligned (i.e., has X+ forward, Y+ left and Z+ up), this is needed to correctly align 'base' with the 'Base' coordinate system of the UR controller. -->
<origin rpy="0 0 3.141592653589793" xyz="0 0 0"/>
<parent link="base_link"/>
<child link="base"/>
</joint>
<!-- ROS-Industrial 'flange' frame - attachment point for EEF models -->
<link name="flange"/>
<joint name="wrist_3-flange" type="fixed">
<parent link="wrist_3_link"/>
<child link="flange"/>
<origin rpy="0 -1.5707963267948966 -1.5707963267948966" xyz="0 0 0"/>
</joint>
<!-- ROS-Industrial 'tool0' frame - all-zeros tool frame -->
<link name="tool0"/>
<joint name="flange-tool0" type="fixed">
<!-- default toolframe - X+ left, Y+ up, Z+ front -->
<origin rpy="1.5707963267948966 0 1.5707963267948966" xyz="0 0 0"/>
<parent link="flange"/>
<child link="tool0"/>
</joint>


<link name="tool_base">
            <visual>
                <origin
                    xyz="0 0 0"
                    rpy="0 0 0" />
                <geometry>
                    <mesh filename="file://$(find mm_description)/meshes/tool/suction_tool.stl" />
                </geometry>
                <material name="">
                    <color rgba="0.75294 0.75294 0.75294 1" />
                </material>
            </visual>
            <collision>
                <origin
                    xyz="0 0 0"
                    rpy="0 0 0" />
                <geometry>
                    <mesh filename="file://$(find mm_description)/meshes/tool/suction_tool.stl" />
                </geometry>
            </collision>
        </link>
        <joint name="tool_base-tool_tip" type="fixed">
            <origin xyz="0 0 0.1780" rpy="0 0 0"/>
            <parent link="tool_base"/>
            <child link="tool_tip"/>
        </joint>
        <link name="tool_tip"/>

  <joint name="tool0-tool" type="fixed">
    <origin xyz="0 0 0" rpy="0 0 0"/>
    <parent link="tool0"/>
    <child link="tool_base"/>
  </joint>
</robot>
