<?xml version="1.0" encoding="utf-8"?>
<!-- This urdf was automatically created by SolidWorks to urdf Exporter! Originally created by Stephen Brawner (brawner@gmail.com) 
     Commit Version: 1.6.0-1-g15f4949  Build Version: 1.6.7594.29634
     For more information, please see http://wiki.ros.org/sw_urdf_exporter -->
<robot xmlns:xacro="http://www.ros.org/wiki/xacro" name="FW01_urdf">

  <link name="virtual0">
  </link>
  <link name="virtual1">
  </link>
  <link name="virtual2">
  </link>
  <!-- <link name="virtual_base">
  </link> -->

  <joint name="virtual_joint1" type="prismatic">
    <origin rpy="0 0 0" xyz="0 0 0"/>
    <parent link="virtual0"/>
    <child link="virtual1"/>
    <axis xyz="1 0 0"/>
    <limit effort="87" lower="-999999" upper="999999" velocity="4.0"/>
  </joint>
  <joint name="virtual_joint2" type="prismatic">
    <origin rpy="0 0 0" xyz="0 0 0"/>
    <parent link="virtual1"/>
    <child link="virtual2"/>
    <axis xyz="0 1 0"/>
    <limit effort="87" lower="-999999" upper="999999" velocity="4.0"/>
  </joint>
  <joint name="virtual_joint3" type="revolute">
    <origin rpy="0 0 0" xyz="0 0 0"/>
    <parent link="virtual2"/>
    <child link="base_footprint"/>
    <axis xyz="0 0 1"/>
    <limit effort="87" lower="-999999" upper="999999" velocity="4.0"/>
  </joint>

  <link name="base_link">
    <parent link="virtual2"/>
    <inertial>
      <origin xyz="0.031466 0.014072 -0.020061" rpy="0 0 0" />
      <mass value="14.32" />
      <inertia ixx="0.11358" ixy="-3.0877E-06" ixz="6.0298E-05" iyy="0.24445" iyz="9.39E-06" izz="0.34372" />
    </inertial>
    <visual>
      <origin xyz="0 0 0" rpy="0 0 0" />
      <geometry>
        <mesh filename="package://yhs_description/meshes/base_link.STL" />
      </geometry>
      <material name="">
        <color rgba="0.79216 0.81961 0.93333 1" />
      </material>
    </visual>
    <collision>
      <origin xyz="0 0 0" rpy="0 0 0" />
      <geometry>
        <mesh filename="package://yhs_description/meshes/base_link.STL" />
        <parent link="virtual2"/>/fo
      </geometry>
    </collision>
  </link>



  
  <link name="front_left_susp_link">
    <inertial>
      <origin xyz="-5.1097E-08 0.049715 -0.1212" rpy="0 0 0" />
      <mass value="0.346" />
      <inertia ixx="0.0020072" ixy="-2.2534E-11" ixz="-1.4296E-09" iyy="0.0017745" iyz="0.00057301" izz="0.00069133" />
    </inertial>
    <visual>
      <origin xyz="0 0 0" rpy="0 0 0" />
      <geometry>
        <mesh filename="package://yhs_description/meshes/front_left_susp_link.STL" />
      </geometry>
      <material name="">
        <color rgba="0.79216 0.81961 0.93333 1" />
      </material>
    </visual>
    <collision>
      <origin xyz="0 0 0" rpy="0 0 0" />
      <geometry>
        <mesh filename="package://yhs_description/meshes/front_left_susp_link.STL" />
      </geometry>
    </collision>
  </link>
  <joint name="front_left_susp_joint" type="fixed">
    <origin xyz="0.23599 0.22433 0" rpy="0 0 ${pi}" />
    <parent link="base_link" />
    <child link="front_left_susp_link" />
    <axis xyz="0 0 -1" />
    <limit lower="0" upper="6.284" effort="50" velocity="10" />
  </joint>
  <link name="front_left_wheel_link">
    <inertial>
      <origin xyz="1.32981591960402E-07 -0.00728100515200261 3.00438927902658E-08" rpy="0 0 0" />
      <mass value="0.69595185951443" />
      <inertia ixx="0.00962890716020916" ixy="-5.26701909143794E-08" ixz="-1.16862671417673E-07" iyy="0.0175039932460916" iyz="-1.70472520582187E-08" izz="0.00962917068994773" />
    </inertial>
    <visual>
      <origin xyz="0 0 0" rpy="0 0 0" />
      <geometry>
        <mesh filename="package://yhs_description/meshes/front_left_wheel_link.STL" />
      </geometry>
      <material name="">
        <color rgba="0.792156862745098 0.819607843137255 0.933333333333333 1" />
      </material>
    </visual>
    <collision>
      <origin xyz="0 0 0" rpy="1.571 0 0" />
      <geometry>
        <cylinder radius="0.120" length="0.082" />
        <!-- <mesh filename="package://yhs_description/meshes/front_left_wheel_link.STL" /> -->
      </geometry>
    </collision>
  </link>
  <joint name="front_left_wheel_joint" type="fixed">
    <origin xyz="0 0 -0.2037" rpy="0 0 0" />
    <parent link="front_left_susp_link" />
    <child link="front_left_wheel_link" />
    <axis xyz="0 1 0" />
  </joint>
  <link name="front_right_susp_link">
    <inertial>
      <origin xyz="5.1097E-08 -0.049715 -0.1212" rpy="0 0 0" />
      <mass value="0.346" />
      <inertia ixx="0.0020072" ixy="-2.2534E-11" ixz="1.4296E-09" iyy="0.0017745" iyz="-0.00057301" izz="0.00069133" />
    </inertial>
    <visual>
      <origin xyz="0 0 0" rpy="0 0 0" />
      <geometry>
        <mesh filename="package://yhs_description/meshes/front_right_susp_link.STL" />
      </geometry>
      <material name="">
        <color rgba="0.79216 0.81961 0.93333 1" />
      </material>
    </visual>
    <collision>
      <origin xyz="0 0 0" rpy="0 0 0" />
      <geometry>
        <mesh filename="package://yhs_description/meshes/front_right_susp_link.STL" />
      </geometry>
    </collision>
  </link>
  <joint name="front_right_susp_joint" type="fixed">
    <origin xyz="0.23599 -0.19567 0" rpy="0 0 ${pi}" />
    <parent link="base_link" />
    <child link="front_right_susp_link" />
    <axis xyz="0 0 -1" />
    <limit lower="0" upper="6.284" effort="50" velocity="10" />
  </joint>
  <link name="front_right_wheel_link">
    <inertial>
      <origin xyz="-1.333830094985E-07 0.00728100515717683 2.97484438194218E-08" rpy="0 0 0" />
      <mass value="0.69595185831376" />
      <inertia ixx="0.00962890715562323" ixy="-5.26667479408471E-08" ixz="1.16868412194413E-07" iyy="0.0175039932407535" iyz="1.70433287817619E-08" izz="0.0096291706889769" />
    </inertial>
    <visual>
      <origin xyz="0 0 0" rpy="0 0 0" />
      <geometry>
        <mesh filename="package://yhs_description/meshes/front_right_wheel_link.STL" />
      </geometry>
      <material name="">
        <color rgba="0.792156862745098 0.819607843137255 0.933333333333333 1" />
      </material>
    </visual>
    <collision>
      <origin xyz="0 0 0" rpy="1.571 0 0" />
      <geometry>
        <cylinder radius="0.120" length="0.082" />
        <!-- <mesh filename="package://yhs_description/meshes/front_right_wheel_link.STL" /> -->
      </geometry>
    </collision>
  </link>
  <joint name="front_right_wheel_joint" type="fixed">
    <origin xyz="0 0 -0.2037" rpy="0 0 0" />
    <parent link="front_right_susp_link" />
    <child link="front_right_wheel_link" />
    <axis xyz="0 1 0" />
  </joint>
  <link name="rear_left_susp_link">
    <inertial>
      <origin xyz="-5.1097E-08 0.049715 -0.1212" rpy="0 0 0" />
      <mass value="0.346" />
      <inertia ixx="0.0020072" ixy="-2.2534E-11" ixz="-1.4296E-09" iyy="0.0017745" iyz="0.00057301" izz="0.00069133" />
    </inertial>
    <visual>
      <origin xyz="0 0 0" rpy="0 0 0" />
      <geometry>
        <mesh filename="package://yhs_description/meshes/rear_left_susp_link.STL" />
      </geometry>
      <material name="">
        <color rgba="0.79216 0.81961 0.93333 1" />
      </material>
    </visual>
    <collision>
      <origin xyz="0 0 0" rpy="0 0 0" />
      <geometry>
        <mesh filename="package://yhs_description/meshes/rear_left_susp_link.STL" />
      </geometry>
    </collision>
  </link>
  <joint name="rear_left_susp_joint" type="fixed">
    <origin xyz="-0.16401 0.22433 0" rpy="0 0 ${pi}" />
    <parent link="base_link" />
    <child link="rear_left_susp_link" />
    <axis xyz="0 0 -1" />
    <limit lower="0" upper="6.284" effort="50" velocity="10" />
  </joint>
  <link name="rear_left_wheel_link">
    <inertial>
      <origin xyz="1.3328E-07 -0.007281 2.9931E-08" rpy="0 0 0" />
      <mass value="0.696" />
      <inertia ixx="0.0096289" ixy="-5.267E-08" ixz="-1.1686E-07" iyy="0.017504" iyz="-1.7046E-08" izz="0.0096292" />
    </inertial>
    <visual>
      <origin xyz="0 0 0" rpy="0 0 0" />
      <geometry>
        <mesh filename="package://yhs_description/meshes/rear_left_wheel_link.STL" />
      </geometry>
      <material name="">
        <color rgba="0.79216 0.81961 0.93333 1" />
      </material>
    </visual>
    <collision>
      <origin xyz="0 0 0" rpy="1.571 0 0" />
      <geometry>
        <cylinder radius="0.120" length="0.082" />
        <!-- <mesh filename="package://yhs_description/meshes/rear_left_wheel_link.STL" /> -->
      </geometry>
    </collision>
  </link>
  <joint name="rear_left_wheel_joint" type="fixed">
    <origin xyz="0 0 -0.2037" rpy="0 0 0" />
    <parent link="rear_left_susp_link" />
    <child link="rear_left_wheel_link" />
    <axis xyz="0 1 0" />
  </joint>
  <link name="rear_right_susp_link">
    <inertial>
      <origin xyz="5.1097E-08 -0.049715 -0.1212" rpy="0 0 0" />
      <mass value="0.346" />
      <inertia ixx="0.0020072" ixy="-2.2534E-11" ixz="1.4296E-09" iyy="0.0017745" iyz="-0.00057301" izz="0.00069133" />
    </inertial>
    <visual>
      <origin xyz="0 0 0" rpy="0 0 0" />
      <geometry>
        <mesh filename="package://yhs_description/meshes/rear_right_susp_link.STL" />
      </geometry>
      <material name="">
        <color rgba="0.79216 0.81961 0.93333 1" />
      </material>
    </visual>
    <collision>
      <origin xyz="0 0 0" rpy="0 0 0" />
      <geometry>
        <mesh filename="package://yhs_description/meshes/rear_right_susp_link.STL" />
      </geometry>
    </collision>
  </link>
  <joint name="rear_right_susp_joint" type="fixed">
    <origin xyz="-0.16401 -0.19567 0" rpy="0 0 ${pi}" />
    <parent link="base_link" />
    <child link="rear_right_susp_link" />
    <axis xyz="0 0 -1" />
    <limit lower="0" upper="6.284" effort="50" velocity="10" />
  </joint>
  <link name="rear_right_wheel_link">
    <inertial>
      <origin xyz="-1.3286E-07 0.007281 2.9858E-08" rpy="0 0 0" />
      <mass value="0.696" />
      <inertia ixx="0.0096289" ixy="-5.2669E-08" ixz="1.1687E-07" iyy="0.017504" iyz="1.7048E-08" izz="0.0096292" />
    </inertial>
    <visual>
      <origin xyz="0 0 0" rpy="0 0 0" />
      <geometry>
        <mesh filename="package://yhs_description/meshes/rear_right_wheel_link.STL" />
      </geometry>
      <material name="">
        <color rgba="0.79216 0.81961 0.93333 1" />
      </material>
    </visual>
    <collision>
      <origin xyz="0 0 0" rpy="1.571 0 0" />
      <geometry>
        <cylinder radius="0.120" length="0.082" />
        <!-- <mesh filename="package://yhs_description/meshes/rear_right_wheel_link.STL" /> -->
      </geometry>
    </collision>
  </link>
  <joint name="rear_right_wheel_joint" type="fixed">
    <origin xyz="0 0 -0.2037" rpy="0 0 0" />
    <parent link="rear_right_susp_link" />
    <child link="rear_right_wheel_link" />
    <axis xyz="0 -1 0" />
  </joint>
  
  <!--<link name="photoneo_pan_link">
    <inertial>
      <origin xyz="1.3878E-17 -7.2685E-16 -0.199" rpy="0 0 0" />
      <mass value="0.78922" />
      <inertia ixx="0.010757" ixy="2.7617E-33" ixz="6.3245E-19" iyy="0.010757" iyz="-3.8438E-17" izz="0.00024561" />
    </inertial>
    <visual>
      <origin xyz="0 0 0" rpy="0 0 0" />
      <geometry>
        <mesh filename="package://yhs_description/meshes/photoneo_pan_link.STL" />
      </geometry>
      <material name="">
        <color rgba="0.79216 0.81961 0.93333 1" />
      </material>
    </visual>
    <collision>
      <origin xyz="0 0 0" rpy="0 0 0" />
      <geometry>
        <mesh filename="package://yhs_description/meshes/photoneo_pan_link.STL" />
      </geometry>
    </collision>
  </link>
  <joint name="photoneo_pan_joint" type="fixed">
    <origin xyz="0.095526 0.01433 0.51894" rpy="0 0 0" />
    <parent link="base_link" />
    <child link="photoneo_pan_link" />
    <axis xyz="0 0 1" />
    <limit lower="-1.0" upper="1.0" effort="50" velocity="10" />
  </joint>-->

  

  <!-- Change the GAZEBO color of suspension links-->
  <gazebo reference="front_left_susp_link">
    <material>Gazebo/Grey</material>
  </gazebo>
  <gazebo reference="front_right_susp_link">
    <material>Gazebo/Grey</material>
  </gazebo>
  <gazebo reference="rear_left_susp_link">
    <material>Gazebo/Grey</material>
  </gazebo>
  <gazebo reference="rear_right_susp_link">
    <material>Gazebo/Grey</material>
  </gazebo>
  <gazebo reference="base_link">
    <material>Gazebo/Grey</material>
  </gazebo>
  <gazebo reference="photoneo_pan_link">
    <material>Gazebo/DarkGrey</material>
  </gazebo>
  <gazebo reference="c5_link">
    <material>Gazebo/DarkGrey</material>
  </gazebo>
  <gazebo reference="front_left_wheel_link">
    <material>Gazebo/Black</material>
  </gazebo>
  <gazebo reference="front_right_wheel_link">
    <material>Gazebo/Black</material>
  </gazebo>
  <gazebo reference="rear_left_wheel_link">
    <material>Gazebo/Black</material>
  </gazebo>
  <gazebo reference="rear_right_wheel_link">
    <material>Gazebo/Black</material>
  </gazebo>
  <gazebo reference="laser_link">
    <material>Gazebo/Red</material>
  </gazebo>

  <!-- This block connects the wheel joint to an actuator (motor), which informs both
    simulation and visualization of the robot -->
  <transmission name="trans_front_left_wheel_joint">
    <type>transmission_interface/SimpleTransmission</type>
    <actuator name="front_left_wheel_joint_motor">
      <mechanicalReduction>1</mechanicalReduction>
    </actuator>
    <joint name="front_left_wheel_joint">
      <hardwareInterface>hardware_interface/VelocityJointInterface</hardwareInterface>
    </joint>
  </transmission>
  <transmission name="trans_front_right_wheel_joint">
    <type>transmission_interface/SimpleTransmission</type>
    <actuator name="front_right_wheel_joint_motor">
      <mechanicalReduction>1</mechanicalReduction>
    </actuator>
    <joint name="front_right_wheel_joint">
      <hardwareInterface>hardware_interface/VelocityJointInterface</hardwareInterface>
    </joint>
  </transmission>

  <transmission name="trans_front_left_susp_joint">
    <type>transmission_interface/SimpleTransmission</type>
    <joint name="front_left_susp_joint">
      <hardwareInterface>hardware_interface/PositionJointInterface</hardwareInterface>
    </joint>
    <actuator name="front_left_susp_joint_motor">
      <hardwareInterface>hardware_interface/PositionJointInterface</hardwareInterface>
      <mechanicalReduction>1</mechanicalReduction>
    </actuator>
  </transmission>
  <transmission name="trans_front_right_susp_joint">
    <type>transmission_interface/SimpleTransmission</type>
    <joint name="front_right_susp_joint">
      <hardwareInterface>hardware_interface/PositionJointInterface</hardwareInterface>
    </joint>
    <actuator name="front_right_susp_joint_motor">
      <hardwareInterface>hardware_interface/PositionJointInterface</hardwareInterface>
      <mechanicalReduction>1</mechanicalReduction>
    </actuator>
  </transmission>
  <transmission name="trans_rear_left_susp_joint">
    <type>transmission_interface/SimpleTransmission</type>
    <joint name="rear_left_susp_joint">
      <hardwareInterface>hardware_interface/PositionJointInterface</hardwareInterface>
    </joint>
    <actuator name="rear_left_susp_joint_motor">
      <hardwareInterface>hardware_interface/PositionJointInterface</hardwareInterface>
      <mechanicalReduction>1</mechanicalReduction>
    </actuator>
  </transmission>
  <transmission name="trans_rear_right_susp_joint">
    <type>transmission_interface/SimpleTransmission</type>
    <joint name="rear_right_susp_joint">
      <hardwareInterface>hardware_interface/PositionJointInterface</hardwareInterface>
    </joint>
    <actuator name="rear_right_motor">
      <hardwareInterface>hardware_interface/PositionJointInterface</hardwareInterface>
      <mechanicalReduction>1</mechanicalReduction>
    </actuator>
  </transmission>
  
  <!--<transmission name="trans_photoneo_pan_joint">
    <type>transmission_interface/SimpleTransmission</type>
    <joint name="photoneo_pan_joint">
      <hardwareInterface>hardware_interface/PositionJointInterface</hardwareInterface>
    </joint>
    <actuator name="photoneo_pan_joint_motor">
      <hardwareInterface>hardware_interface/PositionJointInterface</hardwareInterface>
      <mechanicalReduction>1</mechanicalReduction>
    </actuator>
  </transmission>
  <transmission name="trans_photoneo_tilt_joint">
    <type>transmission_interface/SimpleTransmission</type>
    <joint name="photoneo_tilt_joint">
      <hardwareInterface>hardware_interface/PositionJointInterface</hardwareInterface>
    </joint>
    <actuator name="photoneo_tilt_joint_motor">
      <hardwareInterface>hardware_interface/PositionJointInterface</hardwareInterface>
      <mechanicalReduction>1</mechanicalReduction>
    </actuator>
  </transmission>-->

  <!--The diffential drive won't work properly if there is robotnamespace specified, but moveit controller need robotnamespaces -->
  <gazebo>
    <plugin name="ros_control_ns" filename="libgazebo_ros_control.so">
      <robotNamespace>/</robotNamespace>
        <robotSimType>gazebo_ros_control/DefaultRobotHWSim</robotSimType>
    </plugin>
  </gazebo>
  
  <gazebo>
    <plugin name="joint_state_publisher" filename="libgazebo_ros_joint_state_publisher.so">
      <joint_name>front_left_wheel_joint, front_right_wheel_joint, front_left_susp_joint, front_right_susp_joint, 
        rear_left_susp_joint, rear_right_susp_joint, photoneo_pan_joint, photoneo_tilt_joint</joint_name>
    </plugin>
  </gazebo>

  <!-- specify wheel friction -->
  <gazebo reference="rear_left_wheel_link">
    <mu1 value="100.0" />
    <mu2 value="100.0" />
    <kp value="500000.0" />
    <kd value="1.0" />
    <!-- <material>Gazebo/FlatBlack</material> -->
  </gazebo>
  <!-- specify wheel friction -->
  <gazebo reference="rear_right_wheel_link">
    <mu1 value="100.0" />
    <mu2 value="100.0" />
    <kp value="500000.0" />
    <kd value="1.0" />
    <!-- <material>Gazebo/FlatBlack</material> -->
  </gazebo>
  <!-- specify wheel friction -->
  <gazebo reference="front_left_wheel_link">
    <mu1 value="100.0" />
    <mu2 value="100.0" />
    <kp value="500000.0" />
    <kd value="1.0" />
    <!-- <material>Gazebo/FlatBlack</material> -->
  </gazebo>
  <!-- specify wheel friction -->
  <gazebo reference="front_right_wheel_link">
    <mu1 value="100.0" />
    <mu2 value="100.0" />
    <kp value="500000.0" />
    <kd value="1.0" />
    <!-- <material>Gazebo/FlatBlack</material> -->
  </gazebo>

  <link name="base_footprint">
    <parent link="virtual2" />
    <visual>
      <origin xyz="0 0 0" rpy="0 0 0" />
      <geometry>
        <box size="0.001 0.001 0.001" />
      </geometry>
    </visual>
  </link>
  <!-- Root Linking -->
  <joint name="footprint" type="fixed">
    <origin xyz="0 0 0.32" rpy="0 0 0" />
    <parent link="base_footprint" />
    <child link="base_link" />
  </joint>


  
</robot>
